Workbook

Sheet Übersicht
B2: Aufwandsschätzung — 4 Topics (nach Code-Analyse)
B3: Blitzschutz Willibald Reichenhauser GmbH · laufende Schätzung, Stand 2026-07-27 · Gegenprüfung der Angebote v2 am Bestandscode
B4: Stand 2026-07-27: Terminplanung um Phase 3 (Mitarbeiter-Kalenderansicht, Reuse der Admin-Kalender-Komponente) erweitert. Alle FE-Positionen gegen den Live-Stand (f11dd3f, 10.05.2026, ~6.400 Zeilen) bewertet.
B5: Stundensatz | C5: 69 | D5: ← ändern rechnet alles neu
B6: Auth-Variante | C6: A | D6: ← A = RBAC bleibt Anzeige-Logik · B = serverseitig durchgesetzt
B7: Variante Angebots-Tool | C7: MVP | D7: ← steuert Zeile Angebots-Tool
B10: Topic | C10: Angebot v2 | D10: Neu von | E10: Neu bis | F10: Neu Plan | G10: Δ Plan | H10: Netto Plan | I10: Befund aus der Code-Analyse
B11: 0 · Fundament (neu) | D11: ='Fundament'!E11 | E11: ='Fundament'!F11 | F11: =AVERAGE(D11:E11) | G11: =IF(C11=0,"",F11-C11) | H11: =F11*Übersicht!$C$5 | I11: Auth und Schreibpfad existieren bereits. Es fehlt nur ein Layout für neue Seiten sowie eine Toast-/Validierungs-Konvention.
B12: 1 · Zeichnerrolle / RBAC | C12: 23 | D12: ='RBAC'!E15 | E12: ='RBAC'!F15 | F12: =AVERAGE(D12:E12) | G12: =IF(C12=0,"",F12-C12) | H12: =F12*Übersicht!$C$5 | I12: BE hat keine Identität (ein Shared Secret für alle). FE hat bereits Rollen-Guards, aber zwei hardcodierte E-Mail-Listen.
B13: └ Auth-Härtung (nur Variante B) | D13: =IF($C$6="B",'RBAC'!E23,0) | E13: =IF($C$6="B",'RBAC'!F23,0) | F13: =AVERAGE(D13:E13) | G13: =IF(C13=0,"",F13-C13) | H13: =F13*Übersicht!$C$5 | I13: Nur bei Variante B: MSAL-Token serverseitig validieren, 30 Bestandsrouten migrieren.
B14: 2 · Toggl nachtracken | C14: 21 | D14: ='Toggl'!E16 | E14: ='Toggl'!F16 | F14: =AVERAGE(D14:E14) | G14: =IF(C14=0,"",F14-C14) | H14: =F14*Übersicht!$C$5 | I14: Bestätigt. Zeitraum-Abruf, Upsert und Tages-Payload existieren produktiv.
B15: 3 · Termine / Kalender + Mitarbeiter-Kalender | C15: 27 | D15: ='Terminplanung'!E37 | E15: ='Terminplanung'!F37 | F15: =AVERAGE(D15:E15) | G15: =IF(C15=0,"",F15-C15) | H15: =F15*Übersicht!$C$5 | I15: Keine appointments-Tabelle (3 Textspalten auf projects). UNIQUE KEY blockiert Mehrfachtermine. Mitarbeiter-Kalender = Phase 3 (Reuse der Admin-Kalender-Komponente).
B16: 4 · E-Mail → Angebot | D16: =IF($C$7="nicht beauftragt",0,INDEX('Angebots-Tool'!$C$6:$E$6,MATCH($C$7,'Angebots-Tool'!$C$4:$E$4,0))) | E16: =IF($C$7="nicht beauftragt",0,INDEX('Angebots-Tool'!$C$8:$E$8,MATCH($C$7,'Angebots-Tool'!$C$4:$E$4,0))) | F16: =AVERAGE(D16:E16) | G16: =IF(C16=0,"",F16-C16) | H16: =F16*Übersicht!$C$5 | I16: Spanne unverändert übernommen. Zwei Annahmen darin sind widerlegt — siehe Blatt.
B18: Summe Topics 1–3 + Fundament | C18: =SUM(C11:C16) | D18: =SUM(D11:D15) | E18: =SUM(E11:E15) | F18: =AVERAGE(D18:E18) | G18: =F18-C18 | H18: =F18*Übersicht!$C$5
B19: Gesamt inkl. Angebots-Tool | C19: =SUM(C11:C16) | D19: =SUM(D11:D16) | E19: =SUM(E11:E16) | F19: =AVERAGE(D19:E19) | G19: =F19-C19 | H19: =F19*Übersicht!$C$5
B22: Wie diese Zahlen zustande kommen
B23: · Spalte „Angebot v2" = die bisherigen Zahlen (Stand 2026-07-03). Spalte „Neu" = Gegenprüfung anhand des tatsächlichen Codes.
B24: · Plan = Mittelwert aus von/bis. Die Spanne ist der Puffer, kein Aufschlag.
B25: · 2026-07-27: Mitarbeiter-Kalender als Phase 3 der Terminplanung ergänzt (+8–14 h). Baut auf Phase 1 auf, reine Wiederverwendung.
B26: · Geschätzt von Claude auf Basis einer Code-Analyse — NICHT von Wolfi, der die v2-Zahlen erstellt hat und den Kunden kennt.
B27: · Vor Kundenkontakt gegenprüfen. Gedacht als Gegenprüfung, nicht als Ersatz.
B28: · Das Fundament überschneidet sich teilweise mit dem Roadmap-Punkt „Dashboard-Umbau" (25 h) — nicht doppelt kalkulieren.
B29: · Nicht enthalten: Dashboard-Umbau, PM, Schulung, Wartung.
B31: ✓ Frontend-Repo geklärt
B32: Maßgeblich ist der Live-Checkout /blitzschutz_frontend (f11dd3f, 10.05.2026). Der zuerst analysierte Ordner github_be_fe/… war ein 8 Monate alter Stand desselben Repos.
B33: Offen: die Middleware wurde nicht neu gefetcht (Stand 03.06.2026). Backend-Befunde können bis zu einige Wochen alt sein.

Sheet Fundament
B2: Topic 0 — Fundament (im Angebot v2 nicht enthalten)
B3: Vorarbeit, ohne die kein einziges der vier Features im Frontend landen kann
B5: Phase 0 — Voraussetzungen
B6: Pos. | C6: Leistung | D6: Angebot v2 | E6: von | F6: bis | G6: Befund / Begründung
B7: F1 | C7: Layout / Navigation extrahieren (Basis für neue Seiten) | E7: 5 | F7: 8 | G7: App.vue = 25 Zeilen (router-view + ScrollToTop). Jede View dupliziert ~40 Zeilen Header-Chrome. Neue Seiten brauchen vorher ein Layout.
B8: F2 | C8: Toast-/Feedback- und Validierungs-Konvention etablieren | E8: 2 | F8: 4 | G8: Kein Toast-System, keine Validierungsbibliothek. Fehler werden je Komponente inline gerendert, in EmployeeAssignment.vue:192 nur als console.error.
B9: F3 | C9: ENTFÄLLT — FE↔BE-Auth existiert | E9: 0 | F9: 0 | G9: apiClient.ts:46-48 sendet Bearer VITE_API_TOKEN. Ursprünglich mit 3-5 h angesetzt.
B10: F4 | C10: ENTFÄLLT — Schreibpfad zur API existiert | E10: 0 | F10: 0 | G10: 5 Schreib-Aufrufe an die Middleware, u.a. PUT projects/{id} und PUT construction-sites/{id}. Ursprünglich mit 4-6 h angesetzt.
C11: Zwischensumme Phase 0 | D11: =SUM(D7:D10) | E11: =SUM(E7:E10) | F11: =SUM(F7:F10)
C13: Gesamt | D13: =D11 | E13: =E11 | F13: =F11
B15: Belege aus dem Code
B16: · KORREKTUR 2026-07-21: Die erste Analyse lief gegen einen 8 Monate alten Checkout desselben Repos und war deutlich zu pessimistisch. Maßgeblich ist f11dd3f vom 10.05.2026.
B17: · Das Frontend ist NICHT Nuxt, sondern eine Vite-5-/Vue-3-SPA. Aussagen in Angebotstexten, die „Nuxt UI" voraussetzen, treffen nicht zu.
B18: · Gesamtumfang: ~6.400 Zeilen in 28 Dateien, 4 Routen, 9 Komponenten. Dark-Mode-System, ICS-Export und deutscher Datums-Parser sind vorhanden.
B19: · ENTFALLEN gegenüber der Erstanalyse: FE↔BE-Auth (existiert) und Schreibpfad (existiert) — zusammen 7-11 h, die zu Unrecht angesetzt waren.
B20: · Der Roadmap-Punkt „Dashboard-Umbau" (25 h) deckt F2 teilweise ab — Überschneidung prüfen, nicht doppelt zählen.
B21: · Die Middleware liefert eine unerledigte Anleitung mit: FRONTEND_API_TOKEN_MIGRATION.md.
B22: · Achtung: Der dort dokumentierte Weg (VITE_API_TOKEN im Bearer-Header) legt ein statisches Shared Secret in den Browser-Bundle — aus einer SPA nicht verbergbar.

Sheet RBAC
B2: Topic 1 — Zeichnerrolle / Rollen- & Rechteverwaltung
B3: Angebot v2: 23 h · Neu: 24–36 h (Variante A) bzw. 43–66 h (Variante B)
B5: Variante A — RBAC als Anzeige-Logik
B6: Pos. | C6: Leistung | D6: Angebot v2 | E6: von | F6: bis | G6: Befund / Begründung
B7: A1 | C7: DB: groups + employee_groups (initDatabase-Idiom) | D7: 2 | E7: 2 | F7: 3 | G7: Greenfield, aber trivial. Vorlage: construction_site_employees.
B8: A2 | C8: BE: Group-Service/Controller/Routes + Swagger | D8: 3 | E8: 4 | F8: 6 | G8: Pro Endpoint 50–100 Zeilen Swagger-JSDoc — dominiert den Diff.
B9: A3 | C9: BE: Employee-Schreib-Endpoints (existieren nicht) | E9: 3 | F9: 4 | G9: employeeRoutes.ts hat NUR 4 GET-Routen. Ohne Schreibpfad kann kein Admin Nutzer pflegen.
B10: A4 | C10: FE: Rollen vom Server statt hardcodiert | D10: 2 | E10: 2 | F10: 3 | G10: Store hat BEREITS isPrivilegedUser + isHybridUser (auth.ts:14-23). Zwei hardcodierte Arrays in config.ts:34-40 ersetzen, auf n Rollen verallgemeinern.
B11: A5 | C11: FE: Route Guard auf DB-Rollen umstellen | D11: 3 | E11: 1 | F11: 2 | G11: Der Guard prüft BEREITS Rollen: meta.requiresAdmin / requiresEmployee (router/index.ts:42-66). Es wechselt nur die Datenquelle.
B12: A6 | C12: FE: Berechtigungs-Helper + bestehende v-if-Stellen migrieren | D12: 3 | E12: 2 | F12: 3 | G12: ~14 Stellen in Home.vue, EmployeeView.vue und ConstructionSiteList.vue. Mechanisch, aber mehr als zunächst angenommen.
B13: A7 | C13: FE: Zeichner-Ansicht — Baustellen + Selbstzuweisung | D13: 3 | E13: 3 | F13: 5 | G13: EmployeeAssignment.vue (322 Z.) macht Monteur-Multiselect + Batch-Zuweisung bereits — direkt nachnutzbar.
B14: A8 | C14: FE: Admin-UI Gruppenverwaltung | D14: 6 | E14: 7 | F14: 10 | G14: Bleibt Greenfield: es gibt keine Verwaltungs-UI und keinen Employee-Schreibweg. Formular-Muster ist aber vorhanden (ProjectEditModal).
C15: Zwischensumme Variante A | D15: =SUM(D7:D14) | E15: =SUM(E7:E14) | F15: =SUM(F7:F14)
B17: Variante B — serverseitig durchgesetzt (Zusatz zu A)
B18: Pos. | C18: Leistung | D18: Angebot v2 | E18: von | F18: bis | G18: Befund / Begründung
B19: B1 | C19: BE: MSAL-Token serverseitig validieren (JWKS, Tenant, Cache) | E19: 6 | F19: 10 | G19: Es gibt keinerlei Token-Validierung. @azure/identity ist nicht installiert.
B20: B2 | C20: BE: Identität in die Request-Pipeline (req.user) | E20: 3 | F20: 4 | G20: req.user existiert nicht. Das BE weiß nie, wer aufruft.
B21: B3 | C21: BE: 30 Bestandsrouten auf identitätsbasierte Auth umstellen + testen | E21: 6 | F21: 10 | G21: Alle Routen hängen heute am selben Shared Secret.
B22: B4 | C22: FE: MSAL-Token mitsenden, Refresh, 401-Retry | E22: 4 | F22: 6 | G22: getAccessToken() (msal.ts:405) ist toter Code. MSAL fordert KEINEN API-Scope an — Scope-Registrierung + apiClient-Verdrahtung nötig.
C23: Zwischensumme Variante B | D23: =SUM(D19:D22) | E23: =SUM(E19:E22) | F23: =SUM(F19:F22)
C25: Gesamt | D25: =D15+D23 | E25: =E15+E23 | F25: =F15+F23
B27: Belege aus dem Code
B28: · Die Doku-Aussage „Gruppenlogik nur im FE hardcoded" stimmt — im BE gibt es überhaupt nichts: keine Gruppen, keine Rollen, keine Identität.
B29: · Die gesamte BE-Auth ist EIN Shared Secret (src/middleware/auth.ts), für alle Aufrufer identisch, aus der Env.
B30: · FE-Rollenmodell heute: config.ts:34-40 zwei E-Mail-Listen → auth.ts:14-23 zwei Booleans (isPrivilegedUser, isHybridUser) → ~14 v-if.
B31: · isChef existiert als Spalte auf employees, wird gelesen und ausgeliefert, aber in KEINER Bedingung ausgewertet — totes Flag.
B32: · role auf construction_site_employees ist ein freies Textfeld („Projektleiter"/„Monteur"), kein Rechte-Konzept.
B33: · Position 1.3 des Angebots („Gruppen beim Login in MS Auth Token/Session schreiben", 2 h) beschreibt Arbeit an einem Login, den das BE nicht hat.
B34: · ENTSCHEIDUNG: Variante A schützt vor Verwechslung, nicht vor Absicht. Für ein internes Tool mit 10 Leuten kann das legitim sein — aber bewusst und dem Kunden gegenüber benannt.

Sheet Toggl
B2: Topic 2 — Toggl: vergangene Tage nachtracken
B3: Angebot v2: 21 h · Neu: 18–28 h — im Kern bestätigt
B5: Phase 1 — Umsetzung
B6: Pos. | C6: Leistung | D6: Angebot v2 | E6: von | F6: bis | G6: Befund / Begründung
B7: T1 | C7: BE: timeEntryRoutes + Controller + Swagger + Mount | D7: 2 | E7: 2 | F7: 3 | G7: Es gibt heute gar keinen /api/v1/time-entries-Router.
B8: T2 | C8: BE: Task-main() in importierbare Service-Funktionen refactoren | E8: 2 | F8: 3 | G8: Die Tasks rufen inline process.exit() — aus Express so nicht aufrufbar.
B9: T3 | C9: BE: Mitarbeiter-Filter in getRawTimeEntriesForDate / createPayloadForDate | E9: 1 | F9: 2 | G9: Beide arbeiten heute über ALLE Mitarbeiter, kein Filter vorgesehen.
B10: T4 | C10: BE: Tages-Schleife über den Zeitraum | D10: 3 | E10: 2 | F10: 2 | G10: Der Payload ist bereits pro Mitarbeiter und Tag — nur die Schleife fehlt.
B11: T5 | C11: BE: Langläufer — Job + Status-Polling statt synchronem Request | E11: 3 | F11: 4 | G11: Fest verdrahtete 10 s Pause pro Aufruf (exportDailyTimeEntries.ts:99). Ein 2-Wochen-Export läuft in jedes HTTP-Timeout.
B12: T6 | C12: BE: Pagination bzw. Range-Chunking für /me/time_entries | E12: 2 | F12: 4 | G12: response.data wird ungeprüft übernommen. Für 1 Tag egal, für 1 Monat nicht.
B13: T7 | C13: DB: UNIQUE KEY (toggl_id) + echter Upsert | D13: 2 | E13: 1 | F13: 2 | G13: idx_toggl_id ist nur INDEX, nicht UNIQUE. Duplikatschutz per SELECT-dann-INSERT — bricht bei Parallellauf mit dem 23-Uhr-Cron.
B14: T8 | C14: FE: Formular (Arbeiter, Zeitraum, Status-Feedback) | D14: 5 | E14: 3 | F14: 5 | G14: ProjectEditModal.vue (494 Z.) ist ein vollständiges, kopierbares Formular-Gerüst inkl. Dirty-Check und a11y. apiClient hat alle Verben.
B15: T9 | C15: Test gegen echtes Toggl + Live-Webhook | E15: 2 | F15: 3 | G15: Im Angebot nicht ausgewiesen.
C16: Zwischensumme Phase 1 | D16: =SUM(D7:D15) | E16: =SUM(E7:E15) | F16: =SUM(F7:F15)
C18: Gesamt | D18: =D16 | E18: =E16 | F18: =F16
B20: Belege aus dem Code
B21: · BESTÄTIGT: getTimeEntriesForDateRange (timeEntryService.ts:257-287) existiert fertig inkl. DB-Schreibung.
B22: · BESTÄTIGT: Rate-Limit-Handling mit 3 Retries, 429-Erkennung und Retry-After (togglService.ts:25-43) läuft produktiv.
B23: · BESTÄTIGT: Power Automate bekommt HEUTE SCHON einen POST pro Mitarbeiter pro Tag — „Tage einzeln schicken" ist bereits das Wire-Format, nicht neu zu bauen.
B24: · Das CLI-Skript nimmt bereits einen Zeitraum entgegen: extractDailyTimeEntries.ts:24-29.
B25: · toggl_sync_mode betrifft NUR den Projekt-Sync, nicht die Zeiteinträge — darf die Schätzung nicht aufblähen.
B26: · SCOPE-HEBEL: Maximal 1 Woche pro Export → 16 h bleiben realistisch. Ein ganzer Monat → eher 24 h. Das ist eine Produkt-, keine Technikentscheidung.
B27: · Nebenbefund: Die Power-Automate-URL steht samt SAS-Signatur hartkodiert im Code (powerAutomateService.ts:20), die vorgesehene Env-Variable wird nie gelesen.

Sheet Terminplanung
B2: Topic 3 — Termine für Arbeiter erstellen & verwalten
B3: Angebot v2: 27 h · Neu inkl. Mitarbeiter-Kalender (Phase 3): 53–86 h
B5: Phase 1 — Termine + Admin-Kalender
B6: Pos. | C6: Leistung | D6: Angebot v2 | E6: von | F6: bis | G6: Befund / Begründung
B7: A1 | C7: DB: appointments-Tabelle, Datum/Zeit-Typisierung, fuzzy, mehrtägig | D7: 1 | E7: 3 | F7: 5 | G7: Es gibt KEINE appointments-Tabelle. Nur datum / terminNachVereinbarung / auftragsdatum als VARCHAR/TEXT auf projects, ohne Index.
B8: A2 | C8: DB: appointment_employees + Migration des UNIQUE KEY auf Live-Daten | E8: 4 | F8: 6 | G8: construction_site_employees hat UNIQUE (site, employee) — ein Monteur kann einer Baustelle nur EINMAL zugewiesen werden. Für Mehrfachtermine muss der Key fallen.
B9: A3 | C9: BE: CRUD-Endpoints + Swagger | D9: 3 | E9: 5 | F9: 8 | G9: Bestehende Zuweisungs-Endpoints kennen keinerlei Datum.
B10: A4 | C10: BE: Zeitraum-Endpoint gruppiert nach Mitarbeiter + Indizes | D10: 2 | E10: 3 | F10: 4 | G10: WHERE datum BETWEEN ist auf VARCHAR-Spalten ohne Index nicht sinnvoll möglich.
B11: A5 | C11: FE: Kalender-Bibliothek (calendar.js) auswählen + integrieren | D11: 4 | E11: 7 | F11: 12 | G11: Keine Kalenderbibliothek im Bestand. Gewählt: calendar.js (dieselbe Basis für Admin- und Mitarbeiter-Kalender). utils/date.ts (205 Z.) parst deutsche + ISO-Daten bereits.
B12: A6 | C12: FE: Gesamtansicht + Filter je Monteur | D12: 2 | E12: 4 | F12: 6 | G12: Farbcodierung + Checkbox-Filter.
B13: A7 | C13: FE: Einzelansicht | D13: 2 | E13: 2 | F13: 4 | G13: Freie Tage erkennbar machen.
B14: A8 | C14: FE: Termin-Dialog (Monteur, fuzzy, mehrtägig) | D14: 3 | E14: 4 | F14: 6 | G14: ProjectEditModal.vue bearbeitet terminNachVereinbarung bereits inkl. parseDatum/buildDatum. EmployeeAssignment liefert die Monteur-Auswahl.
B15: A9 | C15: FE: Österreichische Feiertage | D15: 0.5 | E15: 1 | F15: 2 | G15: Ohne Kalender-Plugin selbst zu lösen.
B16: A10 | C16: FE: Offene / fuzzy Termine als Hinweisblock | D16: 1.5 | E16: 2 | F16: 3 | G16: requestService.ts:150 verwirft heute den echten Fuzzy-Wert und schreibt eine Konstante.
C17: Zwischensumme Phase 1 | D17: =SUM(D7:D16) | E17: =SUM(E7:E16) | F17: =SUM(F7:F16)
B19: Phase 2 — WhatsApp-Benachrichtigungen
B20: Pos. | C20: Leistung | D20: Angebot v2 | E20: von | F20: bis | G20: Befund / Begründung
B21: W1 | C21: BE: Benachrichtigung bei Termin-Zuweisung | D21: 2 | E21: 2 | F21: 3 | G21: Gut abgesichert — das Muster läuft produktiv (employeeAssignmentService.ts:55-71).
B22: W2 | C22: BE: Notiz-Entität schaffen + Benachrichtigung | D22: 2 | E22: 4 | F22: 6 | G22: notiz ist EINE überschreibbare TEXT-Spalte auf projects. Keine Zeilen, kein Autor, kein Zeitstempel — es gibt kein „neue Notiz"-Ereignis.
B23: W3 | C23: Templates + Meta-Genehmigung | D23: 1 | E23: 1 | F23: 2 | G23: Twilio Content Templates, positionell ({{1}},{{2}},{{3}}). Genehmigungs-Vorlaufzeit ist extern, nicht in den Stunden.
B24: W4 | C24: whatsapp_number befüllbar machen | D24: 1 | E24: 3 | F24: 5 | G24: Die Spalte EXISTIERT bereits — die 1 h im Angebot ist falsch geschnitten. Es fehlt der Schreibweg: kein Employee-Endpoint, Nummern nur per Seed-Skript.
C25: Zwischensumme Phase 2 | D25: =SUM(D21:D24) | E25: =SUM(E21:E24) | F25: =SUM(F21:F24)
B27: Phase 3 — Mitarbeiter-Kalenderansicht (neu 2026-07-27)
B28: Pos. | C28: Leistung | D28: Angebot v2 | E28: von | F28: bis | G28: Befund / Begründung
B29: M1 | C29: BE: Endpoint — Termine EINES Mitarbeiters im Zeitraum | E29: 1 | F29: 2 | G29: Variante des A4-Endpoints, auf einen Mitarbeiter gefiltert. Vorbild existiert: GET /employees/{id}/construction-sites/with-projects. Das FE kennt die eigene employeeId (auth.ts:47-51) — kein neuer Identitäts-Aufwand unter Variante A.
B30: M2 | C30: FE: Neue Route + View „Mein Kalender" (requiresEmployee) | E30: 2 | F30: 3 | G30: Guard requiresEmployee existiert (router/index.ts). Ohne Layout ~40 Zeilen Header-Chrome duplizieren (vgl. Fundament F1).
B31: M3 | C31: FE: Admin-Kalenderkomponente im Einzel-Modus wiederverwenden | E31: 2 | F31: 4 | G31: Die calendar.js-Integration aus Phase 1 wird als Komponente wiederverwendet, fest auf den eigenen Mitarbeiter gefiltert. Kein zweiter Kalenderbau.
B32: M4 | C32: FE: Zugewiesenes Projekt am Termin anzeigen + Sprung zur Baustelle | E32: 1 | F32: 2 | G32: Bei Zuweisung erscheint der Termin automatisch (appointment_employees aus Phase 1). Projekt-Label + Klick-Ziel ergänzen.
B33: M5 | C33: FE: Einstieg aus „Meine Baustellen" (Tab/Link) + Leerzustand | E33: 1 | F33: 2 | G33: EmployeeView.vue (383 Z., Mitarbeiter-Landingpage) — dort einhängen statt neuer Top-Navigation.
B34: M6 | C34: Test mit echten Zuweisungsdaten | E34: 1 | F34: 1 | G34: Zuweisung → Termin erscheint im richtigen Mitarbeiter-Kalender.
C35: Zwischensumme Phase 3 | D35: =SUM(D29:D34) | E35: =SUM(E29:E34) | F35: =SUM(F29:F34)
C37: Gesamt | D37: =D17+D25+D35 | E37: =E17+E25+E35 | F37: =F17+F25+F35
B39: Belege aus dem Code
B40: · WIDERLEGT: „Terminerfassung existiert bereits in der DB". Existierende Tabellen: construction_sites, projects, employees, time_entries, reserved_toggl_projects, construction_site_toggl_projects, construction_site_employees, requests. Keine appointments.
B41: · terminNachVereinbarung war ursprünglich ein BOOLEAN und enthält heute überwiegend die Strings 'Termin nach Vereinbarung' / 'Termin fehlt'.
B42: · assigned_at auf construction_site_employees ist ein Audit-Zeitstempel (wann wurde die Zeile angelegt), KEIN geplantes Arbeitsdatum.
B43: · PHASE 3 baut auf Phase 1 auf: Datenmodell (appointments, appointment_employees), calendar.js-Komponente und Zeitraum-Endpoint stammen von dort. Ohne Phase 1 ist Phase 3 nicht umsetzbar — die 8–14 h sind reine Wiederverwendung, kein zweiter Kalenderbau.
B44: · OFFENE FRAGE Phase 3: Zeigt der Mitarbeiter-Kalender nur Termine, denen er per appointment_employees zugewiesen ist, ODER alle Termine der Projekte, denen er zugewiesen ist? Ersteres ist sauberer und angenommen; Letzteres bräuchte zusätzlich die (ggf. fuzzy/datumslose) Projekt-Ebene. Klären.
B45: · Sicherheitshinweis Phase 3: Unter Variante A (Shared Secret) kann technisch jeder Mitarbeiter den Kalender jedes anderen abfragen (id im Request austauschbar). Gleiche Ausgangslage wie im ganzen Tool heute — echte Absicherung erst mit RBAC Variante B.
B46: · BESTÄTIGT positiv: WhatsApp läuft über Twilio, produktiv. Die Zuweisungs-Benachrichtigung ist live und eine belastbare Vorlage.
...

Sheet Angebots-Tool
B2: Topic 4 — E-Mail → Angebot: drei Ausbaustufen
B3: Spannen unverändert aus der Variantenübersicht — zwei tragende Annahmen sind jedoch widerlegt (unten)
B4: Kennzahl | C4: MVP | D4: Kern | E4: Vollausbau
B5: Motto | C5: „Der stille Kollege" | D5: „Das Cockpit" | E5: „Der Assistent"
B6: Stunden — von | C6: 108 | D6: 209 | E6: 315
B7: Stunden — Plan | C7: 142 | D7: 272 | E7: 416
B8: Stunden — bis | C8: 175 | D8: 334 | E8: 516
B9: Kosten — von | C9: =C6*Übersicht!$C$5 | D9: =D6*Übersicht!$C$5 | E9: =E6*Übersicht!$C$5
B10: Kosten — Plan | C10: =C7*Übersicht!$C$5 | D10: =D7*Übersicht!$C$5 | E10: =E7*Übersicht!$C$5
B11: Kosten — bis | C11: =C8*Übersicht!$C$5 | D11: =D8*Übersicht!$C$5 | E11: =E8*Übersicht!$C$5
B13: Was die Code-Analyse an den Annahmen ändert
B14: TEILWEISE ZUTREFFEND — „Nuxt-Dashboard": Es ist keine Nuxt-App, sondern eine Vite-/Vue-SPA (~6.400 Zeilen, 4 Routen) ohne Komponentenbibliothek. Formular-Muster, Schreibpfade und Rollen-Guards existieren aber sehr wohl.
B15: → Für das Cockpit heißt das: kein Greenfield, aber jede Eingabemaske ist handgebaute Tailwind-Markup. Ohne Komponentenbibliothek bleiben Editor und Stammdaten-UIs der größte Kostenblock (Kern 50–80 h).
B16: → Es gibt weder ein Toast-System noch eine Validierungsbibliothek — bei einem formularlastigen Cockpit ein realer Zusatzposten.
B17: BESTÄTIGT — „voice_requests als erprobte Vorlage für Architektur UND UI-Muster": die Aussage hält.
B18: → Architektur: Persistenz-Form und LLM-Aufruf. requests hat eine JSON-Spalte extracted_data und ein source-ENUM, das sich billig um 'email' erweitern lässt.
B19: → UI-Muster: VoiceRecorder.vue, VoiceRequestPlayer.vue und OpenRequestsView.vue (463 Z., Admin-Inbox mit Erledigt/Löschen) existieren — eine Freigabe-Inbox ist damit real vorgezeichnet.
B20: → Kein Zustandsautomat: nur ein done-Boolean. Kein pending/failed/needs_review, kein Fehlerfeld, kein Retry-Zähler.
B21: → Verarbeitung ist Fire-and-Forget (promise.catch). Stürzt sie ab, wird NIE eine Zeile geschrieben — für eine verlorene Kundenmail nicht tragbar.
B22: BESTÄTIGT: OpenAI läuft produktiv (GPT-4o-mini für Extraktion, Whisper für Transkription, DeepL für Übersetzung). Der Kunde akzeptiert LLM-Daten in einem menschlich geprüften Formular.
B23: BESTÄTIGT als Greenfield (war bekannt): Microsoft Graph fehlt vollständig, kein E-Mail-Empfang, keine Dokumentgenerierung, keine Queue.
B25: Einordnung
... B29: · Die Empfehlung „Einstieg über MVP" wird durch die Analyse eher gestärkt: kleinster Frontend-Anteil, damit geringste Abhängigkeit vom Fundament.
